Workbook

Sheet Enero Ventas
A1: COSTANERA GRILL · ENERO 2026 · REGISTRO DE VENTAS (SIMULACIÓN)
A2: Datos inventados para ejercicio de capacitación. Sin validez fiscal ni contable. IVA calculado con fórmula sobre base imponible.
A4: Fecha | B4: Tipo comprobante | C4: Número | D4: Cliente | E4: CUIT cliente (ficticio) | F4: Concepto | G4: Cantidad | H4: Neto gravado | I4: Alícuota IVA | J4: IVA débito | K4: Total | L4: Medio de cobro
A5: 46023 | B5: Factura A | C5: 0001-00001001 | D5: Consumidor final | E5: 30-70051000-1 | F5: Parrilla y cortes | G5: 1 | H5: 128737 | I5: 0.21 | J5: =ROUND(H5*I5,2) -> 27034.77 | K5: =ROUND(H5+J5,2) -> 155771.77 | L5: Efectivo
A6: 46024 | B6: Factura B | C6: 0001-00001002 | D6: Hotel Dársena (FICTICIO) | F6: Menú ejecutivo | G6: 2 | H6: 51682 | I6: 0.21 | J6: =ROUND(H6*I6,2) -> 10853.22 | K6: =ROUND(H6+J6,2) -> 62535.22 | L6: Transferencia
A7: 46025 | B7: Factura B | C7: 0001-00001003 | D7: Consumidor final | F7: Cortes premium | G7: 3 | H7: 64628 | I7: 0.21 | J7: =ROUND(H7*I7,2) -> 13571.88 | K7: =ROUND(H7+J7,2) -> 78199.88 | L7: Tarjeta de débito
A8: 46026 | B8: Factura B | C8: 0001-00001004 | D8: Consultora Río (FICTICIA) | F8: Bebidas y cubiertos | G8: 4 | H8: 77574 | I8: 0.21 | J8: =ROUND(H8*I8,2) -> 16290.54 | K8: =ROUND(H8+J8,2) -> 93864.54 | L8: Mercado Pago
A9: 46027 | B9: Factura B | C9: 0001-00001005 | D9: Estudio Madero (FICTICIO) | F9: Parrilla y cortes | G9: 5 | H9: 90520 | I9: 0.21 | J9: =ROUND(H9*I9,2) -> 19009.2 | K9: =ROUND(H9+J9,2) -> 109529.2 | L9: Tarjeta de crédito
A10: 46028 | B10: Factura B | C10: 0001-00001006 | D10: Consumidor final | F10: Menú ejecutivo | G10: 6 | H10: 103466 | I10: 0.21 | J10: =ROUND(H10*I10,2) -> 21727.86 | K10: =ROUND(H10+J10,2) -> 125193.86 | L10: Efectivo
A11: 46029 | B11: Factura B | C11: 0001-00001007 | D11: Consumidor final | F11: Cortes premium | G11: 1 | H11: 116412 | I11: 0.21 | J11: =ROUND(H11*I11,2) -> 24446.52 | K11: =ROUND(H11+J11,2) -> 140858.52 | L11: Transferencia
A12: 46030 | B12: Factura B | C12: 0001-00001008 | D12: Consumidor final | F12: Bebidas y cubiertos | G12: 2 | H12: 129358 | I12: 0.21 | J12: =ROUND(H12*I12,2) -> 27165.18 | K12: =ROUND(H12+J12,2) -> 156523.18 | L12: Tarjeta de débito
A13: 46031 | B13: Factura B | C13: 0001-00001009 | D13: Consumidor final | F13: Parrilla y cortes | G13: 3 | H13: 52303 | I13: 0.21 | J13: =ROUND(H13*I13,2) -> 10983.63 | K13: =ROUND(H13+J13,2) -> 63286.63 | L13: Mercado Pago
A14: 46032 | B14: Factura B | C14: 0001-00001010 | D14: Empresa de Eventos Sur (FICTICIA) | F14: Menú ejecutivo | G14: 4 | H14: 65249 | I14: 0.21 | J14: =ROUND(H14*I14,2) -> 13702.29 | K14: =ROUND(H14+J14,2) -> 78951.29 | L14: Tarjeta de crédito
A15: 46033 | B15: Factura A | C15: 0001-00001011 | D15: Consumidor final | E15: 30-70053210-3 | F15: Cortes premium | G15: 5 | H15: 78195 | I15: 0.21 | J15: =ROUND(H15*I15,2) -> 16420.95 | K15: =ROUND(H15+J15,2) -> 94615.95 | L15: Efectivo
A16: 46034 | B16: Factura B | C16: 0001-00001012 | D16: Agencia Costera (FICTICIA) | F16: Bebidas y cubiertos | G16: 6 | H16: 91141 | I16: 0.21 | J16: =ROUND(H16*I16,2) -> 19139.61 | K16: =ROUND(H16+J16,2) -> 110280.61 | L16: Transferencia
A17: 46035 | B17: Factura B | C17: 0001-00001013 | D17: Consumidor final | F17: Parrilla y cortes | G17: 1 | H17: 104087 | I17: 0.21 | J17: =ROUND(H17*I17,2) -> 21858.27 | K17: =ROUND(H17+J17,2) -> 125945.27 | L17: Tarjeta de débito
A18: 46036 | B18: Factura B | C18: 0001-00001014 | D18: Hotel Dársena (FICTICIO) | F18: Menú ejecutivo | G18: 2 | H18: 117033 | I18: 0.21 | J18: =ROUND(H18*I18,2) -> 24576.93 | K18: =ROUND(H18+J18,2) -> 141609.93 | L18: Mercado Pago
A19: 46037 | B19: Factura B | C19: 0001-00001015 | D19: Consumidor final | F19: Cortes premium | G19: 3 | H19: 129979 | I19: 0.21 | J19: =ROUND(H19*I19,2) -> 27295.59 | K19: =ROUND(H19+J19,2) -> 157274.59 | L19: Tarjeta de crédito
A20: 46038 | B20: Factura B | C20: 0001-00001016 | D20: Consultora Río (FICTICIA) | F20: Bebidas y cubiertos | G20: 4 | H20: 52924 | I20: 0.21 | J20: =ROUND(H20*I20,2) -> 11114.04 | K20: =ROUND(H20+J20,2) -> 64038.04 | L20: Efectivo
A21: 46039 | B21: Factura B | C21: 0001-00001017 | D21: Estudio Madero (FICTICIO) | F21: Parrilla y cortes | G21: 5 | H21: 65870 | I21: 0.21 | J21: =ROUND(H21*I21,2) -> 13832.7 | K21: =ROUND(H21+J21,2) -> 79702.7 | L21: Transferencia
A22: 46040 | B22: Factura B | C22: 0001-00001018 | D22: Consumidor final | F22: Menú ejecutivo | G22: 6 | H22: 78816 | I22: 0.21 | J22: =ROUND(H22*I22,2) -> 16551.36 | K22: =ROUND(H22+J22,2) -> 95367.36 | L22: Tarjeta de débito
A23: 46041 | B23: Factura B | C23: 0001-00001019 | D23: Consumidor final | F23: Cortes premium | G23: 1 | H23: 91762 | I23: 0.21 | J23: =ROUND(H23*I23,2) -> 19270.02 | K23: =ROUND(H23+J23,2) -> 111032.02 | L23: Mercado Pago
A24: 46042 | B24: Factura B | C24: 0001-00001020 | D24: Consumidor final | F24: Bebidas y cubiertos | G24: 2 | H24: 104708 | I24: 0.21 | J24: =ROUND(H24*I24,2) -> 21988.68 | K24: =ROUND(H24+J24,2) -> 126696.68 | L24: Tarjeta de crédito
A25: 46043 | B25: Factura A | C25: 0001-00001021 | D25: Consumidor final | E25: 30-70055420-5 | F25: Parrilla y cortes | G25: 3 | H25: 117654 | I25: 0.21 | J25: =ROUND(H25*I25,2) -> 24707.34 | K25: =ROUND(H25+J25,2) -> 142361.34 | L25: Efectivo
A26: 46044 | B26: Factura B | C26: 0001-00001022 | D26: Empresa de Eventos Sur (FICTICIA) | F26: Menú ejecutivo | G26: 4 | H26: 130600 | I26: 0.21 | J26: =ROUND(H26*I26,2) -> 27426 | K26: =ROUND(H26+J26,2) -> 158026 | L26: Transferencia
A27: 46045 | B27: Factura B | C27: 0001-00001023 | D27: Consumidor final | F27: Cortes premium | G27: 5 | H27: 53545 | I27: 0.21 | J27: =ROUND(H27*I27,2) -> 11244.45 | K27: =ROUND(H27+J27,2) -> 64789.45 | L27: Tarjeta de débito
A28: 46046 | B28: Factura B | C28: 0001-00001024 | D28: Agencia Costera (FICTICIA) | F28: Bebidas y cubiertos | G28: 6 | H28: 66491 | I28: 0.21 | J28: =ROUND(H28*I28,2) -> 13963.11 | K28: =ROUND(H28+J28,2) -> 80454.11 | L28: Mercado Pago
A29: 46047 | B29: Factura B | C29: 0001-00001025 | D29: Consumidor final | F29: Parrilla y cortes | G29: 1 | H29: 79437 | I29: 0.21 | J29: =ROUND(H29*I29,2) -> 16681.77 | K29: =ROUND(H29+J29,2) -> 96118.77 | L29: Tarjeta de crédito
A30: 46048 | B30: Factura B | C30: 0001-00001026 | D30: Hotel Dársena (FICTICIO) | F30: Menú ejecutivo | G30: 2 | H30: 92383 | I30: 0.21 | J30: =ROUND(H30*I30,2) -> 19400.43 | K30: =ROUND(H30+J30,2) -> 111783.43 | L30: Efectivo
A31: 46049 | B31: Factura B | C31: 0001-00001027 | D31: Consumidor final | F31: Cortes premium | G31: 3 | H31: 105329 | I31: 0.21 | J31: =ROUND(H31*I31,2) -> 22119.09 | K31: =ROUND(H31+J31,2) -> 127448.09 | L31: Transferencia
A32: 46050 | B32: Factura B | C32: 0001-00001028 | D32: Consultora Río (FICTICIA) | F32: Bebidas y cubiertos | G32: 4 | H32: 118275 | I32: 0.21 | J32: =ROUND(H32*I32,2) -> 24837.75 | K32: =ROUND(H32+J32,2) -> 143112.75 | L32: Tarjeta de débito
A33: 46023 | B33: Factura B | C33: 0001-00001029 | D33: Estudio Madero (FICTICIO) | F33: Parrilla y cortes | G33: 5 | H33: 131221 | I33: 0.21 | J33: =ROUND(H33*I33,2) -> 27556.41 | K33: =ROUND(H33+J33,2) -> 158777.41 | L33: Mercado Pago
A34: 46024 | B34: Factura B | C34: 0001-00001030 | D34: Consumidor final | F34: Menú ejecutivo | G34: 6 | H34: 54166 | I34: 0.21 | J34: =ROUND(H34*I34,2) -> 11374.86 | K34: =ROUND(H34+J34,2) -> 65540.86 | L34: Tarjeta de crédito
A35: 46025 | B35: Factura A | C35: 0001-00001031 | D35: Consumidor final | E35: 30-70057630-7 | F35: Cortes premium | G35: 1 | H35: 67112 | I35: 0.21 | J35: =ROUND(H35*I35,2) -> 14093.52 | K35: =ROUND(H35+J35,2) -> 81205.52 | L35: Efectivo
A36: 46026 | B36: Factura B | C36: 0001-00001032 | D36: Consumidor final | F36: Bebidas y cubiertos | G36: 2 | H36: 80058 | I36: 0.21 | J36: =ROUND(H36*I36,2) -> 16812.18 | K36: =ROUND(H36+J36,2) -> 96870.18 | L36: Transferencia
A37: 46027 | B37: Factura B | C37: 0001-00001033 | D37: Consumidor final | F37: Parrilla y cortes | G37: 3 | H37: 93004 | I37: 0.21 | J37: =ROUND(H37*I37,2) -> 19530.84 | K37: =ROUND(H37+J37,2) -> 112534.84 | L37: Tarjeta de débito
A38: 46028 | B38: Factura B | C38: 0001-00001034 | D38: Empresa de Eventos Sur (FICTICIA) | F38: Menú ejecutivo | G38: 4 | H38: 105950 | I38: 0.21 | J38: =ROUND(H38*I38,2) -> 22249.5 | K38: =ROUND(H38+J38,2) -> 128199.5 | L38: Mercado Pago
A39: 46029 | B39: Factura B | C39: 0001-00001035 | D39: Consumidor final | F39: Cortes premium | G39: 5 | H39: 118896 | I39: 0.21 | J39: =ROUND(H39*I39,2) -> 24968.16 | K39: =ROUND(H39+J39,2) -> 143864.16 | L39: Tarjeta de crédito
A40: 46030 | B40: Factura B | C40: 0001-00001036 | D40: Agencia Costera (FICTICIA) | F40: Bebidas y cubiertos | G40: 6 | H40: 131842 | I40: 0.21 | J40: =ROUND(H40*I40,2) -> 27686.82 | K40: =ROUND(H40+J40,2) -> 159528.82 | L40: Efectivo
A41: 46031 | B41: Factura B | C41: 0001-00001037 | D41: Consumidor final | F41: Parrilla y cortes | G41: 1 | H41: 54787 | I41: 0.21 | J41: =ROUND(H41*I41,2) -> 11505.27 | K41: =ROUND(H41+J41,2) -> 66292.27 | L41: Transferencia
...

Sheet Enero Gastos
A1: COSTANERA GRILL · ENERO 2026 · REGISTRO DE COMPRAS Y GASTOS (SIMULACIÓN)
A2: Proveedores y comprobantes ficticios. Alícuotas ilustrativas; verificar normativa aplicable en un caso real.
A4: Fecha | B4: Proveedor | C4: CUIT proveedor (ficticio) | D4: Tipo comprobante | E4: Categoría | F4: Detalle | G4: Neto gravado | H4: Alícuota IVA | I4: IVA crédito | J4: Total | K4: Medio de pago
A5: 46024 | B5: Frigorífico La Pampa (FICTICIO) | C5: 30-70123456-1 | D5: Factura A | E5: Carne | F5: Compra de carne para operación | G5: 215353 | H5: 0.105 | I5: =ROUND(G5*H5,2) -> 22612.07 | J5: =ROUND(G5+I5,2) -> 237965.07 | K5: Efectivo
A6: 46027 | B6: Carnes del Sur (FICTICIO) | C6: 30-70987654-2 | D6: Factura B | E6: Carne | F6: Compra de carne para operación | G6: 180030 | H6: 0.105 | I6: =ROUND(G6*H6,2) -> 18903.15 | J6: =ROUND(G6+I6,2) -> 198933.15 | K6: Tarjeta de débito
A7: 46030 | B7: Bebidas Río (FICTICIO) | C7: 30-71234567-3 | D7: Factura B | E7: Bebidas | F7: Compra de bebidas para operación | G7: 94278 | H7: 0.21 | I7: =ROUND(G7*H7,2) -> 19798.38 | J7: =ROUND(G7+I7,2) -> 114076.38 | K7: Tarjeta de crédito
A8: 46033 | B8: Distribuidora Malbec (FICTICIO) | C8: 30-72345678-4 | D8: Factura A | E8: Bebidas | F8: Compra de bebidas para operación | G8: 56754 | H8: 0.21 | I8: =ROUND(G8*H8,2) -> 11918.34 | J8: =ROUND(G8+I8,2) -> 68672.34 | K8: Transferencia
A9: 46036 | B9: Edenor - ejemplo didáctico | C9: 30-54567891-2 | D9: Factura B | E9: Electricidad | F9: Compra de electricidad para operación | G9: 103573 | H9: 0.21 | I9: =ROUND(G9*H9,2) -> 21750.33 | J9: =ROUND(G9+I9,2) -> 125323.33 | K9: Mercado Pago
A10: 46039 | B10: Metrogas - ejemplo didáctico | C10: 30-65789123-4 | D10: Factura B | E10: Gas | F10: Compra de gas para operación | G10: 79939 | H10: 0.21 | I10: =ROUND(G10*H10,2) -> 16787.19 | J10: =ROUND(G10+I10,2) -> 96726.19 | K10: Efectivo
A11: 46042 | B11: Fibra Puerto (FICTICIO) | C11: 30-67891234-5 | D11: Factura A | E11: Internet | F11: Compra de internet para operación | G11: 29718 | H11: 0.21 | I11: =ROUND(G11*H11,2) -> 6240.78 | J11: =ROUND(G11+I11,2) -> 35958.78 | K11: Tarjeta de débito
A12: 46045 | B12: Limpieza del Puerto (FICTICIO) | C12: 30-68912345-6 | D12: Factura B | E12: Limpieza | F12: Compra de limpieza para operación | G12: 50045 | H12: 0.21 | I12: =ROUND(G12*H12,2) -> 10509.45 | J12: =ROUND(G12+I12,2) -> 60554.45 | K12: Tarjeta de crédito
A13: 46048 | B13: Envases del Plata (FICTICIO) | C13: 30-69123456-7 | D13: Factura B | E13: Insumos | F13: Compra de insumos para operación | G13: 52468 | H13: 0.21 | I13: =ROUND(G13*H13,2) -> 11018.28 | J13: =ROUND(G13+I13,2) -> 63486.28 | K13: Transferencia
A14: 46024 | B14: Alquiler local Puerto Madero (FICTICIO) | C14: 30-61234567-8 | D14: Factura A | E14: Alquiler | F14: Compra de alquiler para operación | G14: 131393 | H14: 0.21 | I14: =ROUND(G14*H14,2) -> 27592.53 | J14: =ROUND(G14+I14,2) -> 158985.53 | K14: Mercado Pago
A15: 46027 | B15: Mantenimiento Parrillero (FICTICIO) | C15: 30-63456789-1 | D15: Factura B | E15: Mantenimiento | F15: Compra de mantenimiento para operación | G15: 48409 | H15: 0.21 | I15: =ROUND(G15*H15,2) -> 10165.89 | J15: =ROUND(G15+I15,2) -> 58574.89 | K15: Efectivo
A16: 46030 | B16: Panificados del Puerto (FICTICIO) | C16: 30-64567891-3 | D16: Factura B | E16: Alimentos | F16: Compra de alimentos para operación | G16: 43167 | H16: 0.21 | I16: =ROUND(G16*H16,2) -> 9065.07 | J16: =ROUND(G16+I16,2) -> 52232.07 | K16: Tarjeta de débito
... A22: 46048 | B22: Papelería Administrativa (FICTICIO) | C22: 30-61234578-9 | D22: Factura B | E22: Administración | F22: Compra de administración para operación | G22: 12369 | H22: 0.21 | I22: =ROUND(G22*H22,2) -> 2597.49 | J22: =ROUND(G22+I22,2) -> 14966.49 | K22: Tarjeta de crédito

Sheet Febrero Ventas
A1: COSTANERA GRILL · FEBRERO 2026 · REGISTRO DE VENTAS (SIMULACIÓN)
A2: Datos inventados para ejercicio de capacitación. Sin validez fiscal ni contable. IVA calculado con fórmula sobre base imponible.
A4: Fecha | B4: Tipo comprobante | C4: Número | D4: Cliente | E4: CUIT cliente (ficticio) | F4: Concepto | G4: Cantidad | H4: Neto gravado | I4: Alícuota IVA | J4: IVA débito | K4: Total | L4: Medio de cobro
A5: 46054 | B5: Factura A | C5: 0001-00002001 | D5: Consumidor final | E5: 30-70052547-4 | F5: Menú ejecutivo | G5: 1 | H5: 95724.92 | I5: 0.21 | J5: =ROUND(H5*I5,2) -> 20102.23 | K5: =ROUND(H5+J5,2) -> 115827.15 | L5: Tarjeta de débito
A6: 46055 | B6: Factura B | C6: 0001-00002002 | D6: Consumidor final | F6: Cortes premium | G6: 2 | H6: 38704.22 | I6: 0.21 | J6: =ROUND(H6*I6,2) -> 8127.89 | K6: =ROUND(H6+J6,2) -> 46832.11 | L6: Mercado Pago
A7: 46056 | B7: Factura B | C7: 0001-00002003 | D7: Empresa de Eventos Sur (FICTICIA) | F7: Bebidas y cubiertos | G7: 3 | H7: 48284.26 | I7: 0.21 | J7: =ROUND(H7*I7,2) -> 10139.69 | K7: =ROUND(H7+J7,2) -> 58423.95 | L7: Tarjeta de crédito
A8: 46057 | B8: Factura B | C8: 0001-00002004 | D8: Consumidor final | F8: Parrilla y cortes | G8: 4 | H8: 57864.3 | I8: 0.21 | J8: =ROUND(H8*I8,2) -> 12151.5 | K8: =ROUND(H8+J8,2) -> 70015.8 | L8: Efectivo
A9: 46058 | B9: Factura B | C9: 0001-00002005 | D9: Agencia Costera (FICTICIA) | F9: Menú ejecutivo | G9: 5 | H9: 67444.34 | I9: 0.21 | J9: =ROUND(H9*I9,2) -> 14163.31 | K9: =ROUND(H9+J9,2) -> 81607.65 | L9: Transferencia
A10: 46059 | B10: Factura B | C10: 0001-00002006 | D10: Consumidor final | F10: Cortes premium | G10: 6 | H10: 77024.38 | I10: 0.21 | J10: =ROUND(H10*I10,2) -> 16175.12 | K10: =ROUND(H10+J10,2) -> 93199.5 | L10: Tarjeta de débito
A11: 46060 | B11: Factura B | C11: 0001-00002007 | D11: Hotel Dársena (FICTICIO) | F11: Bebidas y cubiertos | G11: 1 | H11: 86604.42 | I11: 0.21 | J11: =ROUND(H11*I11,2) -> 18186.93 | K11: =ROUND(H11+J11,2) -> 104791.35 | L11: Mercado Pago
A12: 46061 | B12: Factura B | C12: 0001-00002008 | D12: Consumidor final | F12: Parrilla y cortes | G12: 2 | H12: 96184.46 | I12: 0.21 | J12: =ROUND(H12*I12,2) -> 20198.74 | K12: =ROUND(H12+J12,2) -> 116383.2 | L12: Tarjeta de crédito
A13: 46062 | B13: Factura B | C13: 0001-00002009 | D13: Consultora Río (FICTICIA) | F13: Menú ejecutivo | G13: 3 | H13: 39163.76 | I13: 0.21 | J13: =ROUND(H13*I13,2) -> 8224.39 | K13: =ROUND(H13+J13,2) -> 47388.15 | L13: Efectivo
A14: 46063 | B14: Factura B | C14: 0001-00002010 | D14: Estudio Madero (FICTICIO) | F14: Cortes premium | G14: 4 | H14: 48743.8 | I14: 0.21 | J14: =ROUND(H14*I14,2) -> 10236.2 | K14: =ROUND(H14+J14,2) -> 58980 | L14: Transferencia
A15: 46064 | B15: Factura A | C15: 0001-00002011 | D15: Consumidor final | E15: 30-70054757-6 | F15: Bebidas y cubiertos | G15: 5 | H15: 58323.84 | I15: 0.21 | J15: =ROUND(H15*I15,2) -> 12248.01 | K15: =ROUND(H15+J15,2) -> 70571.85 | L15: Tarjeta de débito
A16: 46065 | B16: Factura B | C16: 0001-00002012 | D16: Consumidor final | F16: Parrilla y cortes | G16: 6 | H16: 67903.88 | I16: 0.21 | J16: =ROUND(H16*I16,2) -> 14259.81 | K16: =ROUND(H16+J16,2) -> 82163.69 | L16: Mercado Pago
A17: 46066 | B17: Factura B | C17: 0001-00002013 | D17: Consumidor final | F17: Menú ejecutivo | G17: 1 | H17: 77483.92 | I17: 0.21 | J17: =ROUND(H17*I17,2) -> 16271.62 | K17: =ROUND(H17+J17,2) -> 93755.54 | L17: Tarjeta de crédito
A18: 46067 | B18: Factura B | C18: 0001-00002014 | D18: Consumidor final | F18: Cortes premium | G18: 2 | H18: 87063.96 | I18: 0.21 | J18: =ROUND(H18*I18,2) -> 18283.43 | K18: =ROUND(H18+J18,2) -> 105347.39 | L18: Efectivo
A19: 46068 | B19: Factura B | C19: 0001-00002015 | D19: Empresa de Eventos Sur (FICTICIA) | F19: Bebidas y cubiertos | G19: 3 | H19: 96644 | I19: 0.21 | J19: =ROUND(H19*I19,2) -> 20295.24 | K19: =ROUND(H19+J19,2) -> 116939.24 | L19: Transferencia
A20: 46069 | B20: Factura B | C20: 0001-00002016 | D20: Consumidor final | F20: Parrilla y cortes | G20: 4 | H20: 39623.3 | I20: 0.21 | J20: =ROUND(H20*I20,2) -> 8320.89 | K20: =ROUND(H20+J20,2) -> 47944.19 | L20: Tarjeta de débito
A21: 46070 | B21: Factura B | C21: 0001-00002017 | D21: Agencia Costera (FICTICIA) | F21: Menú ejecutivo | G21: 5 | H21: 49203.34 | I21: 0.21 | J21: =ROUND(H21*I21,2) -> 10332.7 | K21: =ROUND(H21+J21,2) -> 59536.04 | L21: Mercado Pago
A22: 46071 | B22: Factura B | C22: 0001-00002018 | D22: Consumidor final | F22: Cortes premium | G22: 6 | H22: 58783.38 | I22: 0.21 | J22: =ROUND(H22*I22,2) -> 12344.51 | K22: =ROUND(H22+J22,2) -> 71127.89 | L22: Tarjeta de crédito
A23: 46072 | B23: Factura B | C23: 0001-00002019 | D23: Hotel Dársena (FICTICIO) | F23: Bebidas y cubiertos | G23: 1 | H23: 68363.42 | I23: 0.21 | J23: =ROUND(H23*I23,2) -> 14356.32 | K23: =ROUND(H23+J23,2) -> 82719.74 | L23: Efectivo
A24: 46073 | B24: Factura B | C24: 0001-00002020 | D24: Consumidor final | F24: Parrilla y cortes | G24: 2 | H24: 77943.46 | I24: 0.21 | J24: =ROUND(H24*I24,2) -> 16368.13 | K24: =ROUND(H24+J24,2) -> 94311.59 | L24: Transferencia
A25: 46074 | B25: Factura A | C25: 0001-00002021 | D25: Consultora Río (FICTICIA) | E25: 30-70056967-8 | F25: Menú ejecutivo | G25: 3 | H25: 118275 | I25: 0.21 | J25: =ROUND(H25*I25,2) -> 24837.75 | K25: =ROUND(H25+J25,2) -> 143112.75 | L25: Tarjeta de débito
A26: 46075 | B26: Factura B | C26: 0001-00002022 | D26: Estudio Madero (FICTICIO) | F26: Cortes premium | G26: 4 | H26: 131221 | I26: 0.21 | J26: =ROUND(H26*I26,2) -> 27556.41 | K26: =ROUND(H26+J26,2) -> 158777.41 | L26: Mercado Pago
A27: 46076 | B27: Factura B | C27: 0001-00002023 | D27: Consumidor final | F27: Bebidas y cubiertos | G27: 5 | H27: 54166 | I27: 0.21 | J27: =ROUND(H27*I27,2) -> 11374.86 | K27: =ROUND(H27+J27,2) -> 65540.86 | L27: Tarjeta de crédito
A28: 46077 | B28: Factura B | C28: 0001-00002024 | D28: Consumidor final | F28: Parrilla y cortes | G28: 6 | H28: 67112 | I28: 0.21 | J28: =ROUND(H28*I28,2) -> 14093.52 | K28: =ROUND(H28+J28,2) -> 81205.52 | L28: Efectivo
A29: 46078 | B29: Factura B | C29: 0001-00002025 | D29: Consumidor final | F29: Menú ejecutivo | G29: 1 | H29: 80058 | I29: 0.21 | J29: =ROUND(H29*I29,2) -> 16812.18 | K29: =ROUND(H29+J29,2) -> 96870.18 | L29: Transferencia
A30: 46079 | B30: Factura B | C30: 0001-00002026 | D30: Consumidor final | F30: Cortes premium | G30: 2 | H30: 93004 | I30: 0.21 | J30: =ROUND(H30*I30,2) -> 19530.84 | K30: =ROUND(H30+J30,2) -> 112534.84 | L30: Tarjeta de débito
A31: 46080 | B31: Factura B | C31: 0001-00002027 | D31: Empresa de Eventos Sur (FICTICIA) | F31: Bebidas y cubiertos | G31: 3 | H31: 105950 | I31: 0.21 | J31: =ROUND(H31*I31,2) -> 22249.5 | K31: =ROUND(H31+J31,2) -> 128199.5 | L31: Mercado Pago
A32: 46081 | B32: Factura B | C32: 0001-00002028 | D32: Consumidor final | F32: Parrilla y cortes | G32: 4 | H32: 118896 | I32: 0.21 | J32: =ROUND(H32*I32,2) -> 24968.16 | K32: =ROUND(H32+J32,2) -> 143864.16 | L32: Tarjeta de crédito
A33: 46054 | B33: Factura B | C33: 0001-00002029 | D33: Agencia Costera (FICTICIA) | F33: Menú ejecutivo | G33: 5 | H33: 131842 | I33: 0.21 | J33: =ROUND(H33*I33,2) -> 27686.82 | K33: =ROUND(H33+J33,2) -> 159528.82 | L33: Efectivo
A34: 46055 | B34: Factura B | C34: 0001-00002030 | D34: Consumidor final | F34: Cortes premium | G34: 6 | H34: 54787 | I34: 0.21 | J34: =ROUND(H34*I34,2) -> 11505.27 | K34: =ROUND(H34+J34,2) -> 66292.27 | L34: Transferencia
A35: 46056 | B35: Factura A | C35: 0001-00002031 | D35: Hotel Dársena (FICTICIO) | E35: 30-70059177-2 | F35: Bebidas y cubiertos | G35: 1 | H35: 67733 | I35: 0.21 | J35: =ROUND(H35*I35,2) -> 14223.93 | K35: =ROUND(H35+J35,2) -> 81956.93 | L35: Tarjeta de débito
A36: 46057 | B36: Factura B | C36: 0001-00002032 | D36: Consumidor final | F36: Parrilla y cortes | G36: 2 | H36: 80679 | I36: 0.21 | J36: =ROUND(H36*I36,2) -> 16942.59 | K36: =ROUND(H36+J36,2) -> 97621.59 | L36: Mercado Pago
A37: 46058 | B37: Factura B | C37: 0001-00002033 | D37: Consultora Río (FICTICIA) | F37: Menú ejecutivo | G37: 3 | H37: 93625 | I37: 0.21 | J37: =ROUND(H37*I37,2) -> 19661.25 | K37: =ROUND(H37+J37,2) -> 113286.25 | L37: Tarjeta de crédito
A38: 46059 | B38: Factura B | C38: 0001-00002034 | D38: Estudio Madero (FICTICIO) | F38: Cortes premium | G38: 4 | H38: 106571 | I38: 0.21 | J38: =ROUND(H38*I38,2) -> 22379.91 | K38: =ROUND(H38+J38,2) -> 128950.91 | L38: Efectivo
A39: 46060 | B39: Factura B | C39: 0001-00002035 | D39: Consumidor final | F39: Bebidas y cubiertos | G39: 5 | H39: 119517 | I39: 0.21 | J39: =ROUND(H39*I39,2) -> 25098.57 | K39: =ROUND(H39+J39,2) -> 144615.57 | L39: Transferencia
A40: 46061 | B40: Factura B | C40: 0001-00002036 | D40: Consumidor final | F40: Parrilla y cortes | G40: 6 | H40: 42462 | I40: 0.21 | J40: =ROUND(H40*I40,2) -> 8917.02 | K40: =ROUND(H40+J40,2) -> 51379.02 | L40: Tarjeta de débito
A41: 46062 | B41: Factura B | C41: 0001-00002037 | D41: Consumidor final | F41: Menú ejecutivo | G41: 1 | H41: 55408 | I41: 0.21 | J41: =ROUND(H41*I41,2) -> 11635.68 | K41: =ROUND(H41+J41,2) -> 67043.68 | L41: Mercado Pago
...

Sheet Febrero Gastos
A1: COSTANERA GRILL · FEBRERO 2026 · REGISTRO DE COMPRAS Y GASTOS (SIMULACIÓN)
A2: Proveedores y comprobantes ficticios. Alícuotas ilustrativas; verificar normativa aplicable en un caso real.
A4: Fecha | B4: Proveedor | C4: CUIT proveedor (ficticio) | D4: Tipo comprobante | E4: Categoría | F4: Detalle | G4: Neto gravado | H4: Alícuota IVA | I4: IVA crédito | J4: Total | K4: Medio de pago
A5: 46055 | B5: Frigorífico La Pampa (FICTICIO) | C5: 30-70123456-1 | D5: Factura A | E5: Carne | F5: Compra de carne para operación | G5: 1350447 | H5: 0.105 | I5: =ROUND(G5*H5,2) -> 141796.94 | J5: =ROUND(G5+I5,2) -> 1492243.9 | K5: Tarjeta de débito
A6: 46058 | B6: Carnes del Sur (FICTICIO) | C6: 30-70987654-2 | D6: Factura B | E6: Carne | F6: Compra de carne para operación | G6: 759444 | H6: 0.105 | I6: =ROUND(G6*H6,2) -> 79741.62 | J6: =ROUND(G6+I6,2) -> 839185.62 | K6: Tarjeta de crédito
A7: 46061 | B7: Bebidas Río (FICTICIO) | C7: 30-71234567-3 | D7: Factura B | E7: Bebidas | F7: Compra de bebidas para operación | G7: 537738 | H7: 0.21 | I7: =ROUND(G7*H7,2) -> 112924.98 | J7: =ROUND(G7+I7,2) -> 650662.98 | K7: Transferencia
A8: 46064 | B8: Distribuidora Malbec (FICTICIO) | C8: 30-72345678-4 | D8: Factura A | E8: Bebidas | F8: Compra de bebidas para operación | G8: 367071 | H8: 0.21 | I8: =ROUND(G8*H8,2) -> 77084.91 | J8: =ROUND(G8+I8,2) -> 444155.91 | K8: Mercado Pago
A9: 46067 | B9: Edenor - ejemplo didáctico | C9: 30-54567891-2 | D9: Factura B | E9: Electricidad | F9: Compra de electricidad para operación | G9: 595367 | H9: 0.21 | I9: =ROUND(G9*H9,2) -> 125027.07 | J9: =ROUND(G9+I9,2) -> 720394.07 | K9: Efectivo
A10: 46070 | B10: Metrogas - ejemplo didáctico | C10: 30-65789123-4 | D10: Factura B | E10: Gas | F10: Compra de gas para operación | G10: 510806 | H10: 0.21 | I10: =ROUND(G10*H10,2) -> 107269.26 | J10: =ROUND(G10+I10,2) -> 618075.26 | K10: Tarjeta de débito
A11: 46073 | B11: Fibra Puerto (FICTICIO) | C11: 30-67891234-5 | D11: Factura A | E11: Internet | F11: Compra de internet para operación | G11: 136995 | H11: 0.21 | I11: =ROUND(G11*H11,2) -> 28768.95 | J11: =ROUND(G11+I11,2) -> 165763.95 | K11: Tarjeta de crédito
A12: 46076 | B12: Limpieza del Puerto (FICTICIO) | C12: 30-68912345-6 | D12: Factura B | E12: Limpieza | F12: Compra de limpieza para operación | G12: 238526 | H12: 0.21 | I12: =ROUND(G12*H12,2) -> 50090.46 | J12: =ROUND(G12+I12,2) -> 288616.46 | K12: Transferencia
A13: 46079 | B13: Envases del Plata (FICTICIO) | C13: 30-69123456-7 | D13: Factura B | E13: Insumos | F13: Compra de insumos para operación | G13: 191636 | H13: 0.21 | I13: =ROUND(G13*H13,2) -> 40243.56 | J13: =ROUND(G13+I13,2) -> 231879.56 | K13: Mercado Pago
A14: 46055 | B14: Alquiler local Puerto Madero (FICTICIO) | C14: 30-61234567-8 | D14: Factura A | E14: Alquiler | F14: Compra de alquiler para operación | G14: 643802 | H14: 0.21 | I14: =ROUND(G14*H14,2) -> 135198.42 | J14: =ROUND(G14+I14,2) -> 779000.42 | K14: Efectivo
A15: 46058 | B15: Mantenimiento Parrillero (FICTICIO) | C15: 30-63456789-1 | D15: Factura B | E15: Mantenimiento | F15: Compra de mantenimiento para operación | G15: 253233 | H15: 0.21 | I15: =ROUND(G15*H15,2) -> 53178.93 | J15: =ROUND(G15+I15,2) -> 306411.93 | K15: Tarjeta de débito
A16: 46061 | B16: Panificados del Puerto (FICTICIO) | C16: 30-64567891-3 | D16: Factura B | E16: Alimentos | F16: Compra de alimentos para operación | G16: 208345 | H16: 0.21 | I16: =ROUND(G16*H16,2) -> 43752.45 | J16: =ROUND(G16+I16,2) -> 252097.45 | K16: Tarjeta de crédito
... A22: 46079 | B22: Papelería Administrativa (FICTICIO) | C22: 30-61234578-9 | D22: Factura B | E22: Administración | F22: Compra de administración para operación | G22: 141112 | H22: 0.21 | I22: =ROUND(G22*H22,2) -> 29633.52 | J22: =ROUND(G22+I22,2) -> 170745.52 | K22: Transferencia

Sheet Marzo Ventas
A1: COSTANERA GRILL · MARZO 2026 · REGISTRO DE VENTAS (SIMULACIÓN)
A2: Datos inventados para ejercicio de capacitación. Sin validez fiscal ni contable. IVA calculado con fórmula sobre base imponible.
A4: Fecha | B4: Tipo comprobante | C4: Número | D4: Cliente | E4: CUIT cliente (ficticio) | F4: Concepto | G4: Cantidad | H4: Neto gravado | I4: Alícuota IVA | J4: IVA débito | K4: Total | L4: Medio de cobro
A5: 46082 | B5: Factura A | C5: 0001-00003001 | D5: Consumidor final | E5: 30-70054094-7 | F5: Cortes premium | G5: 1 | H5: 129979 | I5: 0.21 | J5: =ROUND(H5*I5,2) -> 27295.59 | K5: =ROUND(H5+J5,2) -> 157274.59 | L5: Tarjeta de crédito
A6: 46083 | B6: Factura B | C6: 0001-00003002 | D6: Consultora Río (FICTICIA) | F6: Bebidas y cubiertos | G6: 2 | H6: 52924 | I6: 0.21 | J6: =ROUND(H6*I6,2) -> 11114.04 | K6: =ROUND(H6+J6,2) -> 64038.04 | L6: Efectivo
A7: 46084 | B7: Factura B | C7: 0001-00003003 | D7: Estudio Madero (FICTICIO) | F7: Parrilla y cortes | G7: 3 | H7: 65870 | I7: 0.21 | J7: =ROUND(H7*I7,2) -> 13832.7 | K7: =ROUND(H7+J7,2) -> 79702.7 | L7: Transferencia
A8: 46085 | B8: Factura B | C8: 0001-00003004 | D8: Consumidor final | F8: Menú ejecutivo | G8: 4 | H8: 78816 | I8: 0.21 | J8: =ROUND(H8*I8,2) -> 16551.36 | K8: =ROUND(H8+J8,2) -> 95367.36 | L8: Tarjeta de débito
A9: 46086 | B9: Factura B | C9: 0001-00003005 | D9: Consumidor final | F9: Cortes premium | G9: 5 | H9: 91762 | I9: 0.21 | J9: =ROUND(H9*I9,2) -> 19270.02 | K9: =ROUND(H9+J9,2) -> 111032.02 | L9: Mercado Pago
A10: 46087 | B10: Factura B | C10: 0001-00003006 | D10: Consumidor final | F10: Bebidas y cubiertos | G10: 6 | H10: 104708 | I10: 0.21 | J10: =ROUND(H10*I10,2) -> 21988.68 | K10: =ROUND(H10+J10,2) -> 126696.68 | L10: Tarjeta de crédito
A11: 46088 | B11: Factura B | C11: 0001-00003007 | D11: Consumidor final | F11: Parrilla y cortes | G11: 1 | H11: 117654 | I11: 0.21 | J11: =ROUND(H11*I11,2) -> 24707.34 | K11: =ROUND(H11+J11,2) -> 142361.34 | L11: Efectivo
A12: 46089 | B12: Factura B | C12: 0001-00003008 | D12: Empresa de Eventos Sur (FICTICIA) | F12: Menú ejecutivo | G12: 2 | H12: 130600 | I12: 0.21 | J12: =ROUND(H12*I12,2) -> 27426 | K12: =ROUND(H12+J12,2) -> 158026 | L12: Transferencia
A13: 46090 | B13: Factura B | C13: 0001-00003009 | D13: Consumidor final | F13: Cortes premium | G13: 3 | H13: 53545 | I13: 0.21 | J13: =ROUND(H13*I13,2) -> 11244.45 | K13: =ROUND(H13+J13,2) -> 64789.45 | L13: Tarjeta de débito
A14: 46091 | B14: Factura B | C14: 0001-00003010 | D14: Agencia Costera (FICTICIA) | F14: Bebidas y cubiertos | G14: 4 | H14: 66491 | I14: 0.21 | J14: =ROUND(H14*I14,2) -> 13963.11 | K14: =ROUND(H14+J14,2) -> 80454.11 | L14: Mercado Pago
A15: 46092 | B15: Factura A | C15: 0001-00003011 | D15: Consumidor final | E15: 30-70056304-1 | F15: Parrilla y cortes | G15: 5 | H15: 79437 | I15: 0.21 | J15: =ROUND(H15*I15,2) -> 16681.77 | K15: =ROUND(H15+J15,2) -> 96118.77 | L15: Tarjeta de crédito
A16: 46093 | B16: Factura B | C16: 0001-00003012 | D16: Hotel Dársena (FICTICIO) | F16: Menú ejecutivo | G16: 6 | H16: 92383 | I16: 0.21 | J16: =ROUND(H16*I16,2) -> 19400.43 | K16: =ROUND(H16+J16,2) -> 111783.43 | L16: Efectivo
A17: 46094 | B17: Factura B | C17: 0001-00003013 | D17: Consumidor final | F17: Cortes premium | G17: 1 | H17: 105329 | I17: 0.21 | J17: =ROUND(H17*I17,2) -> 22119.09 | K17: =ROUND(H17+J17,2) -> 127448.09 | L17: Transferencia
A18: 46095 | B18: Factura B | C18: 0001-00003014 | D18: Consultora Río (FICTICIA) | F18: Bebidas y cubiertos | G18: 2 | H18: 118275 | I18: 0.21 | J18: =ROUND(H18*I18,2) -> 24837.75 | K18: =ROUND(H18+J18,2) -> 143112.75 | L18: Tarjeta de débito
A19: 46096 | B19: Factura B | C19: 0001-00003015 | D19: Estudio Madero (FICTICIO) | F19: Parrilla y cortes | G19: 3 | H19: 131221 | I19: 0.21 | J19: =ROUND(H19*I19,2) -> 27556.41 | K19: =ROUND(H19+J19,2) -> 158777.41 | L19: Mercado Pago
A20: 46097 | B20: Factura B | C20: 0001-00003016 | D20: Consumidor final | F20: Menú ejecutivo | G20: 4 | H20: 54166 | I20: 0.21 | J20: =ROUND(H20*I20,2) -> 11374.86 | K20: =ROUND(H20+J20,2) -> 65540.86 | L20: Tarjeta de crédito
A21: 46098 | B21: Factura B | C21: 0001-00003017 | D21: Consumidor final | F21: Cortes premium | G21: 5 | H21: 67112 | I21: 0.21 | J21: =ROUND(H21*I21,2) -> 14093.52 | K21: =ROUND(H21+J21,2) -> 81205.52 | L21: Efectivo
A22: 46099 | B22: Factura B | C22: 0001-00003018 | D22: Consumidor final | F22: Bebidas y cubiertos | G22: 6 | H22: 80058 | I22: 0.21 | J22: =ROUND(H22*I22,2) -> 16812.18 | K22: =ROUND(H22+J22,2) -> 96870.18 | L22: Transferencia
A23: 46100 | B23: Factura B | C23: 0001-00003019 | D23: Consumidor final | F23: Parrilla y cortes | G23: 1 | H23: 93004 | I23: 0.21 | J23: =ROUND(H23*I23,2) -> 19530.84 | K23: =ROUND(H23+J23,2) -> 112534.84 | L23: Tarjeta de débito
A24: 46101 | B24: Factura B | C24: 0001-00003020 | D24: Empresa de Eventos Sur (FICTICIA) | F24: Menú ejecutivo | G24: 2 | H24: 105950 | I24: 0.21 | J24: =ROUND(H24*I24,2) -> 22249.5 | K24: =ROUND(H24+J24,2) -> 128199.5 | L24: Mercado Pago
A25: 46102 | B25: Factura A | C25: 0001-00003021 | D25: Consumidor final | E25: 30-70058514-3 | F25: Cortes premium | G25: 3 | H25: 118896 | I25: 0.21 | J25: =ROUND(H25*I25,2) -> 24968.16 | K25: =ROUND(H25+J25,2) -> 143864.16 | L25: Tarjeta de crédito
A26: 46103 | B26: Factura B | C26: 0001-00003022 | D26: Agencia Costera (FICTICIA) | F26: Bebidas y cubiertos | G26: 4 | H26: 131842 | I26: 0.21 | J26: =ROUND(H26*I26,2) -> 27686.82 | K26: =ROUND(H26+J26,2) -> 159528.82 | L26: Efectivo
A27: 46104 | B27: Factura B | C27: 0001-00003023 | D27: Consumidor final | F27: Parrilla y cortes | G27: 5 | H27: 54787 | I27: 0.21 | J27: =ROUND(H27*I27,2) -> 11505.27 | K27: =ROUND(H27+J27,2) -> 66292.27 | L27: Transferencia
A28: 46105 | B28: Factura B | C28: 0001-00003024 | D28: Hotel Dársena (FICTICIO) | F28: Menú ejecutivo | G28: 6 | H28: 67733 | I28: 0.21 | J28: =ROUND(H28*I28,2) -> 14223.93 | K28: =ROUND(H28+J28,2) -> 81956.93 | L28: Tarjeta de débito
A29: 46106 | B29: Factura B | C29: 0001-00003025 | D29: Consumidor final | F29: Cortes premium | G29: 1 | H29: 80679 | I29: 0.21 | J29: =ROUND(H29*I29,2) -> 16942.59 | K29: =ROUND(H29+J29,2) -> 97621.59 | L29: Mercado Pago
A30: 46107 | B30: Factura B | C30: 0001-00003026 | D30: Consultora Río (FICTICIA) | F30: Bebidas y cubiertos | G30: 2 | H30: 93625 | I30: 0.21 | J30: =ROUND(H30*I30,2) -> 19661.25 | K30: =ROUND(H30+J30,2) -> 113286.25 | L30: Tarjeta de crédito
A31: 46108 | B31: Factura B | C31: 0001-00003027 | D31: Estudio Madero (FICTICIO) | F31: Parrilla y cortes | G31: 3 | H31: 106571 | I31: 0.21 | J31: =ROUND(H31*I31,2) -> 22379.91 | K31: =ROUND(H31+J31,2) -> 128950.91 | L31: Efectivo
A32: 46109 | B32: Factura B | C32: 0001-00003028 | D32: Consumidor final | F32: Menú ejecutivo | G32: 4 | H32: 119517 | I32: 0.21 | J32: =ROUND(H32*I32,2) -> 25098.57 | K32: =ROUND(H32+J32,2) -> 144615.57 | L32: Transferencia
A33: 46082 | B33: Factura B | C33: 0001-00003029 | D33: Consumidor final | F33: Cortes premium | G33: 5 | H33: 42462 | I33: 0.21 | J33: =ROUND(H33*I33,2) -> 8917.02 | K33: =ROUND(H33+J33,2) -> 51379.02 | L33: Tarjeta de débito
A34: 46083 | B34: Factura B | C34: 0001-00003030 | D34: Consumidor final | F34: Bebidas y cubiertos | G34: 6 | H34: 55408 | I34: 0.21 | J34: =ROUND(H34*I34,2) -> 11635.68 | K34: =ROUND(H34+J34,2) -> 67043.68 | L34: Mercado Pago
A35: 46084 | B35: Factura A | C35: 0001-00003031 | D35: Consumidor final | E35: 30-70060724-5 | F35: Parrilla y cortes | G35: 1 | H35: 68354 | I35: 0.21 | J35: =ROUND(H35*I35,2) -> 14354.34 | K35: =ROUND(H35+J35,2) -> 82708.34 | L35: Tarjeta de crédito
A36: 46085 | B36: Factura B | C36: 0001-00003032 | D36: Empresa de Eventos Sur (FICTICIA) | F36: Menú ejecutivo | G36: 2 | H36: 81300 | I36: 0.21 | J36: =ROUND(H36*I36,2) -> 17073 | K36: =ROUND(H36+J36,2) -> 98373 | L36: Efectivo
A37: 46086 | B37: Factura B | C37: 0001-00003033 | D37: Consumidor final | F37: Cortes premium | G37: 3 | H37: 94246 | I37: 0.21 | J37: =ROUND(H37*I37,2) -> 19791.66 | K37: =ROUND(H37+J37,2) -> 114037.66 | L37: Transferencia
A38: 46087 | B38: Factura B | C38: 0001-00003034 | D38: Agencia Costera (FICTICIA) | F38: Bebidas y cubiertos | G38: 4 | H38: 107192 | I38: 0.21 | J38: =ROUND(H38*I38,2) -> 22510.32 | K38: =ROUND(H38+J38,2) -> 129702.32 | L38: Tarjeta de débito
A39: 46088 | B39: Factura B | C39: 0001-00003035 | D39: Consumidor final | F39: Parrilla y cortes | G39: 5 | H39: 120138 | I39: 0.21 | J39: =ROUND(H39*I39,2) -> 25228.98 | K39: =ROUND(H39+J39,2) -> 145366.98 | L39: Mercado Pago
A40: 46089 | B40: Factura B | C40: 0001-00003036 | D40: Hotel Dársena (FICTICIO) | F40: Menú ejecutivo | G40: 6 | H40: 43083 | I40: 0.21 | J40: =ROUND(H40*I40,2) -> 9047.43 | K40: =ROUND(H40+J40,2) -> 52130.43 | L40: Tarjeta de crédito
A41: 46090 | B41: Factura B | C41: 0001-00003037 | D41: Consumidor final | F41: Cortes premium | G41: 1 | H41: 56029 | I41: 0.21 | J41: =ROUND(H41*I41,2) -> 11766.09 | K41: =ROUND(H41+J41,2) -> 67795.09 | L41: Efectivo
...

Sheet Marzo Gastos
A1: COSTANERA GRILL · MARZO 2026 · REGISTRO DE COMPRAS Y GASTOS (SIMULACIÓN)
A2: Proveedores y comprobantes ficticios. Alícuotas ilustrativas; verificar normativa aplicable en un caso real.
A4: Fecha | B4: Proveedor | C4: CUIT proveedor (ficticio) | D4: Tipo comprobante | E4: Categoría | F4: Detalle | G4: Neto gravado | H4: Alícuota IVA | I4: IVA crédito | J4: Total | K4: Medio de pago
A5: 46083 | B5: Frigorífico La Pampa (FICTICIO) | C5: 30-70123456-1 | D5: Factura A | E5: Carne | F5: Compra de carne para operación | G5: 220275 | H5: 0.105 | I5: =ROUND(G5*H5,2) -> 23128.88 | J5: =ROUND(G5+I5,2) -> 243403.88 | K5: Tarjeta de crédito
A6: 46086 | B6: Carnes del Sur (FICTICIO) | C6: 30-70987654-2 | D6: Factura B | E6: Carne | F6: Compra de carne para operación | G6: 179953 | H6: 0.105 | I6: =ROUND(G6*H6,2) -> 18895.07 | J6: =ROUND(G6+I6,2) -> 198848.07 | K6: Transferencia
A7: 46089 | B7: Bebidas Río (FICTICIO) | C7: 30-71234567-3 | D7: Factura B | E7: Bebidas | F7: Compra de bebidas para operación | G7: 79186 | H7: 0.21 | I7: =ROUND(G7*H7,2) -> 16629.06 | J7: =ROUND(G7+I7,2) -> 95815.06 | K7: Mercado Pago
A8: 46092 | B8: Distribuidora Malbec (FICTICIO) | C8: 30-72345678-4 | D8: Factura A | E8: Bebidas | F8: Compra de bebidas para operación | G8: 61656 | H8: 0.21 | I8: =ROUND(G8*H8,2) -> 12947.76 | J8: =ROUND(G8+I8,2) -> 74603.76 | K8: Efectivo
A9: 46095 | B9: Edenor - ejemplo didáctico | C9: 30-54567891-2 | D9: Factura B | E9: Electricidad | F9: Compra de electricidad para operación | G9: 88481 | H9: 0.21 | I9: =ROUND(G9*H9,2) -> 18581.01 | J9: =ROUND(G9+I9,2) -> 107062.01 | K9: Tarjeta de débito
A10: 46098 | B10: Metrogas - ejemplo didáctico | C10: 30-65789123-4 | D10: Factura B | E10: Gas | F10: Compra de gas para operación | G10: 84837 | H10: 0.21 | I10: =ROUND(G10*H10,2) -> 17815.77 | J10: =ROUND(G10+I10,2) -> 102652.77 | K10: Tarjeta de crédito
A11: 46101 | B11: Fibra Puerto (FICTICIO) | C11: 30-67891234-5 | D11: Factura A | E11: Internet | F11: Compra de internet para operación | G11: 28475 | H11: 0.21 | I11: =ROUND(G11*H11,2) -> 5979.75 | J11: =ROUND(G11+I11,2) -> 34454.75 | K11: Transferencia
A12: 46104 | B12: Limpieza del Puerto (FICTICIO) | C12: 30-68912345-6 | D12: Factura B | E12: Limpieza | F12: Compra de limpieza para operación | G12: 26899 | H12: 0.21 | I12: =ROUND(G12*H12,2) -> 5648.79 | J12: =ROUND(G12+I12,2) -> 32547.79 | K12: Mercado Pago
A13: 46107 | B13: Envases del Plata (FICTICIO) | C13: 30-69123456-7 | D13: Factura B | E13: Insumos | F13: Compra de insumos para operación | G13: 51351 | H13: 0.21 | I13: =ROUND(G13*H13,2) -> 10783.71 | J13: =ROUND(G13+I13,2) -> 62134.71 | K13: Efectivo
A14: 46083 | B14: Alquiler local Puerto Madero (FICTICIO) | C14: 30-61234567-8 | D14: Factura A | E14: Alquiler | F14: Compra de alquiler para operación | G14: 126286 | H14: 0.21 | I14: =ROUND(G14*H14,2) -> 26520.06 | J14: =ROUND(G14+I14,2) -> 152806.06 | K14: Tarjeta de débito
A15: 46086 | B15: Mantenimiento Parrillero (FICTICIO) | C15: 30-63456789-1 | D15: Factura B | E15: Mantenimiento | F15: Compra de mantenimiento para operación | G15: 33279 | H15: 0.21 | I15: =ROUND(G15*H15,2) -> 6988.59 | J15: =ROUND(G15+I15,2) -> 40267.59 | K15: Tarjeta de crédito
A16: 46089 | B16: Panificados del Puerto (FICTICIO) | C16: 30-64567891-3 | D16: Factura B | E16: Alimentos | F16: Compra de alimentos para operación | G16: 61042 | H16: 0.21 | I16: =ROUND(G16*H16,2) -> 12818.82 | J16: =ROUND(G16+I16,2) -> 73860.82 | K16: Transferencia
... A22: 46107 | B22: Papelería Administrativa (FICTICIO) | C22: 30-61234578-9 | D22: Factura B | E22: Administración | F22: Compra de administración para operación | G22: 17150 | H22: 0.21 | I22: =ROUND(G22*H22,2) -> 3601.5 | J22: =ROUND(G22+I22,2) -> 20751.5 | K22: Mercado Pago

Sheet Abril Ventas
A1: COSTANERA GRILL · ABRIL 2026 · REGISTRO DE VENTAS (SIMULACIÓN)
A2: Datos inventados para ejercicio de capacitación. Sin validez fiscal ni contable. IVA calculado con fórmula sobre base imponible.
A4: Fecha | B4: Tipo comprobante | C4: Número | D4: Cliente | E4: CUIT cliente (ficticio) | F4: Concepto | G4: Cantidad | H4: Neto gravado | I4: Alícuota IVA | J4: IVA débito | K4: Total | L4: Medio de cobro
A5: 46113 | B5: Factura A | C5: 0001-00004001 | D5: Empresa de Eventos Sur (FICTICIA) | E5: 30-70055641-2 | F5: Bebidas y cubiertos | G5: 1 | H5: 130600 | I5: 0.21 | J5: =ROUND(H5*I5,2) -> 27426 | K5: =ROUND(H5+J5,2) -> 158026 | L5: Transferencia
A6: 46114 | B6: Factura B | C6: 0001-00004002 | D6: Consumidor final | F6: Parrilla y cortes | G6: 2 | H6: 53545 | I6: 0.21 | J6: =ROUND(H6*I6,2) -> 11244.45 | K6: =ROUND(H6+J6,2) -> 64789.45 | L6: Tarjeta de débito
A7: 46115 | B7: Factura B | C7: 0001-00004003 | D7: Agencia Costera (FICTICIA) | F7: Menú ejecutivo | G7: 3 | H7: 66491 | I7: 0.21 | J7: =ROUND(H7*I7,2) -> 13963.11 | K7: =ROUND(H7+J7,2) -> 80454.11 | L7: Mercado Pago
A8: 46116 | B8: Factura B | C8: 0001-00004004 | D8: Consumidor final | F8: Cortes premium | G8: 4 | H8: 79437 | I8: 0.21 | J8: =ROUND(H8*I8,2) -> 16681.77 | K8: =ROUND(H8+J8,2) -> 96118.77 | L8: Tarjeta de crédito
A9: 46117 | B9: Factura B | C9: 0001-00004005 | D9: Hotel Dársena (FICTICIO) | F9: Bebidas y cubiertos | G9: 5 | H9: 92383 | I9: 0.21 | J9: =ROUND(H9*I9,2) -> 19400.43 | K9: =ROUND(H9+J9,2) -> 111783.43 | L9: Efectivo
A10: 46118 | B10: Factura B | C10: 0001-00004006 | D10: Consumidor final | F10: Parrilla y cortes | G10: 6 | H10: 105329 | I10: 0.21 | J10: =ROUND(H10*I10,2) -> 22119.09 | K10: =ROUND(H10+J10,2) -> 127448.09 | L10: Transferencia
A11: 46119 | B11: Factura B | C11: 0001-00004007 | D11: Consultora Río (FICTICIA) | F11: Menú ejecutivo | G11: 1 | H11: 118275 | I11: 0.21 | J11: =ROUND(H11*I11,2) -> 24837.75 | K11: =ROUND(H11+J11,2) -> 143112.75 | L11: Tarjeta de débito
A12: 46120 | B12: Factura B | C12: 0001-00004008 | D12: Estudio Madero (FICTICIO) | F12: Cortes premium | G12: 2 | H12: 131221 | I12: 0.21 | J12: =ROUND(H12*I12,2) -> 27556.41 | K12: =ROUND(H12+J12,2) -> 158777.41 | L12: Mercado Pago
A13: 46121 | B13: Factura B | C13: 0001-00004009 | D13: Consumidor final | F13: Bebidas y cubiertos | G13: 3 | H13: 54166 | I13: 0.21 | J13: =ROUND(H13*I13,2) -> 11374.86 | K13: =ROUND(H13+J13,2) -> 65540.86 | L13: Tarjeta de crédito
A14: 46122 | B14: Factura B | C14: 0001-00004010 | D14: Consumidor final | F14: Parrilla y cortes | G14: 4 | H14: 67112 | I14: 0.21 | J14: =ROUND(H14*I14,2) -> 14093.52 | K14: =ROUND(H14+J14,2) -> 81205.52 | L14: Efectivo
A15: 46123 | B15: Factura A | C15: 0001-00004011 | D15: Consumidor final | E15: 30-70057851-4 | F15: Menú ejecutivo | G15: 5 | H15: 80058 | I15: 0.21 | J15: =ROUND(H15*I15,2) -> 16812.18 | K15: =ROUND(H15+J15,2) -> 96870.18 | L15: Transferencia
A16: 46124 | B16: Factura B | C16: 0001-00004012 | D16: Consumidor final | F16: Cortes premium | G16: 6 | H16: 93004 | I16: 0.21 | J16: =ROUND(H16*I16,2) -> 19530.84 | K16: =ROUND(H16+J16,2) -> 112534.84 | L16: Tarjeta de débito
A17: 46125 | B17: Factura B | C17: 0001-00004013 | D17: Empresa de Eventos Sur (FICTICIA) | F17: Bebidas y cubiertos | G17: 1 | H17: 105950 | I17: 0.21 | J17: =ROUND(H17*I17,2) -> 22249.5 | K17: =ROUND(H17+J17,2) -> 128199.5 | L17: Mercado Pago
A18: 46126 | B18: Factura B | C18: 0001-00004014 | D18: Consumidor final | F18: Parrilla y cortes | G18: 2 | H18: 118896 | I18: 0.21 | J18: =ROUND(H18*I18,2) -> 24968.16 | K18: =ROUND(H18+J18,2) -> 143864.16 | L18: Tarjeta de crédito
A19: 46127 | B19: Factura B | C19: 0001-00004015 | D19: Agencia Costera (FICTICIA) | F19: Menú ejecutivo | G19: 3 | H19: 131842 | I19: 0.21 | J19: =ROUND(H19*I19,2) -> 27686.82 | K19: =ROUND(H19+J19,2) -> 159528.82 | L19: Efectivo
A20: 46128 | B20: Factura B | C20: 0001-00004016 | D20: Consumidor final | F20: Cortes premium | G20: 4 | H20: 54787 | I20: 0.21 | J20: =ROUND(H20*I20,2) -> 11505.27 | K20: =ROUND(H20+J20,2) -> 66292.27 | L20: Transferencia
A21: 46129 | B21: Factura B | C21: 0001-00004017 | D21: Hotel Dársena (FICTICIO) | F21: Bebidas y cubiertos | G21: 5 | H21: 67733 | I21: 0.21 | J21: =ROUND(H21*I21,2) -> 14223.93 | K21: =ROUND(H21+J21,2) -> 81956.93 | L21: Tarjeta de débito
A22: 46130 | B22: Factura B | C22: 0001-00004018 | D22: Consumidor final | F22: Parrilla y cortes | G22: 6 | H22: 80679 | I22: 0.21 | J22: =ROUND(H22*I22,2) -> 16942.59 | K22: =ROUND(H22+J22,2) -> 97621.59 | L22: Mercado Pago
A23: 46131 | B23: Factura B | C23: 0001-00004019 | D23: Consultora Río (FICTICIA) | F23: Menú ejecutivo | G23: 1 | H23: 93625 | I23: 0.21 | J23: =ROUND(H23*I23,2) -> 19661.25 | K23: =ROUND(H23+J23,2) -> 113286.25 | L23: Tarjeta de crédito
A24: 46132 | B24: Factura B | C24: 0001-00004020 | D24: Estudio Madero (FICTICIO) | F24: Cortes premium | G24: 2 | H24: 106571 | I24: 0.21 | J24: =ROUND(H24*I24,2) -> 22379.91 | K24: =ROUND(H24+J24,2) -> 128950.91 | L24: Efectivo
A25: 46133 | B25: Factura A | C25: 0001-00004021 | D25: Consumidor final | E25: 30-70060061-6 | F25: Bebidas y cubiertos | G25: 3 | H25: 119517 | I25: 0.21 | J25: =ROUND(H25*I25,2) -> 25098.57 | K25: =ROUND(H25+J25,2) -> 144615.57 | L25: Transferencia
A26: 46134 | B26: Factura B | C26: 0001-00004022 | D26: Consumidor final | F26: Parrilla y cortes | G26: 4 | H26: 42462 | I26: 0.21 | J26: =ROUND(H26*I26,2) -> 8917.02 | K26: =ROUND(H26+J26,2) -> 51379.02 | L26: Tarjeta de débito
A27: 46135 | B27: Factura B | C27: 0001-00004023 | D27: Consumidor final | F27: Menú ejecutivo | G27: 5 | H27: 55408 | I27: 0.21 | J27: =ROUND(H27*I27,2) -> 11635.68 | K27: =ROUND(H27+J27,2) -> 67043.68 | L27: Mercado Pago
A28: 46136 | B28: Factura B | C28: 0001-00004024 | D28: Consumidor final | F28: Cortes premium | G28: 6 | H28: 68354 | I28: 0.21 | J28: =ROUND(H28*I28,2) -> 14354.34 | K28: =ROUND(H28+J28,2) -> 82708.34 | L28: Tarjeta de crédito
A29: 46137 | B29: Factura B | C29: 0001-00004025 | D29: Empresa de Eventos Sur (FICTICIA) | F29: Bebidas y cubiertos | G29: 1 | H29: 81300 | I29: 0.21 | J29: =ROUND(H29*I29,2) -> 17073 | K29: =ROUND(H29+J29,2) -> 98373 | L29: Efectivo
A30: 46138 | B30: Factura B | C30: 0001-00004026 | D30: Consumidor final | F30: Parrilla y cortes | G30: 2 | H30: 94246 | I30: 0.21 | J30: =ROUND(H30*I30,2) -> 19791.66 | K30: =ROUND(H30+J30,2) -> 114037.66 | L30: Transferencia
A31: 46139 | B31: Factura B | C31: 0001-00004027 | D31: Agencia Costera (FICTICIA) | F31: Menú ejecutivo | G31: 3 | H31: 107192 | I31: 0.21 | J31: =ROUND(H31*I31,2) -> 22510.32 | K31: =ROUND(H31+J31,2) -> 129702.32 | L31: Tarjeta de débito
A32: 46140 | B32: Factura B | C32: 0001-00004028 | D32: Consumidor final | F32: Cortes premium | G32: 4 | H32: 120138 | I32: 0.21 | J32: =ROUND(H32*I32,2) -> 25228.98 | K32: =ROUND(H32+J32,2) -> 145366.98 | L32: Mercado Pago
A33: 46113 | B33: Factura B | C33: 0001-00004029 | D33: Hotel Dársena (FICTICIO) | F33: Bebidas y cubiertos | G33: 5 | H33: 43083 | I33: 0.21 | J33: =ROUND(H33*I33,2) -> 9047.43 | K33: =ROUND(H33+J33,2) -> 52130.43 | L33: Tarjeta de crédito
A34: 46114 | B34: Factura B | C34: 0001-00004030 | D34: Consumidor final | F34: Parrilla y cortes | G34: 6 | H34: 56029 | I34: 0.21 | J34: =ROUND(H34*I34,2) -> 11766.09 | K34: =ROUND(H34+J34,2) -> 67795.09 | L34: Efectivo
A35: 46115 | B35: Factura A | C35: 0001-00004031 | D35: Consultora Río (FICTICIA) | E35: 30-70062271-8 | F35: Menú ejecutivo | G35: 1 | H35: 68975 | I35: 0.21 | J35: =ROUND(H35*I35,2) -> 14484.75 | K35: =ROUND(H35+J35,2) -> 83459.75 | L35: Transferencia
A36: 46116 | B36: Factura B | C36: 0001-00004032 | D36: Estudio Madero (FICTICIO) | F36: Cortes premium | G36: 2 | H36: 81921 | I36: 0.21 | J36: =ROUND(H36*I36,2) -> 17203.41 | K36: =ROUND(H36+J36,2) -> 99124.41 | L36: Tarjeta de débito
A37: 46117 | B37: Factura B | C37: 0001-00004033 | D37: Consumidor final | F37: Bebidas y cubiertos | G37: 3 | H37: 94867 | I37: 0.21 | J37: =ROUND(H37*I37,2) -> 19922.07 | K37: =ROUND(H37+J37,2) -> 114789.07 | L37: Mercado Pago
A38: 46118 | B38: Factura B | C38: 0001-00004034 | D38: Consumidor final | F38: Parrilla y cortes | G38: 4 | H38: 107813 | I38: 0.21 | J38: =ROUND(H38*I38,2) -> 22640.73 | K38: =ROUND(H38+J38,2) -> 130453.73 | L38: Tarjeta de crédito
A39: 46119 | B39: Factura B | C39: 0001-00004035 | D39: Consumidor final | F39: Menú ejecutivo | G39: 5 | H39: 120759 | I39: 0.21 | J39: =ROUND(H39*I39,2) -> 25359.39 | K39: =ROUND(H39+J39,2) -> 146118.39 | L39: Efectivo
A40: 46120 | B40: Factura B | C40: 0001-00004036 | D40: Consumidor final | F40: Cortes premium | G40: 6 | H40: 43704 | I40: 0.21 | J40: =ROUND(H40*I40,2) -> 9177.84 | K40: =ROUND(H40+J40,2) -> 52881.84 | L40: Transferencia
A41: 46121 | B41: Factura B | C41: 0001-00004037 | D41: Empresa de Eventos Sur (FICTICIA) | F41: Bebidas y cubiertos | G41: 1 | H41: 56650 | I41: 0.21 | J41: =ROUND(H41*I41,2) -> 11896.5 | K41: =ROUND(H41+J41,2) -> 68546.5 | L41: Tarjeta de débito
...

Sheet Abril Gastos
A1: COSTANERA GRILL · ABRIL 2026 · REGISTRO DE COMPRAS Y GASTOS (SIMULACIÓN)
A2: Proveedores y comprobantes ficticios. Alícuotas ilustrativas; verificar normativa aplicable en un caso real.
A4: Fecha | B4: Proveedor | C4: CUIT proveedor (ficticio) | D4: Tipo comprobante | E4: Categoría | F4: Detalle | G4: Neto gravado | H4: Alícuota IVA | I4: IVA crédito | J4: Total | K4: Medio de pago
A5: 46114 | B5: Frigorífico La Pampa (FICTICIO) | C5: 30-70123456-1 | D5: Factura A | E5: Carne | F5: Compra de carne para operación | G5: 222736 | H5: 0.105 | I5: =ROUND(G5*H5,2) -> 23387.28 | J5: =ROUND(G5+I5,2) -> 246123.28 | K5: Transferencia
A6: 46117 | B6: Carnes del Sur (FICTICIO) | C6: 30-70987654-2 | D6: Factura B | E6: Carne | F6: Compra de carne para operación | G6: 122414 | H6: 0.105 | I6: =ROUND(G6*H6,2) -> 12853.47 | J6: =ROUND(G6+I6,2) -> 135267.47 | K6: Mercado Pago
A7: 46120 | B7: Bebidas Río (FICTICIO) | C7: 30-71234567-3 | D7: Factura B | E7: Bebidas | F7: Compra de bebidas para operación | G7: 71640 | H7: 0.21 | I7: =ROUND(G7*H7,2) -> 15044.4 | J7: =ROUND(G7+I7,2) -> 86684.4 | K7: Efectivo
A8: 46123 | B8: Distribuidora Malbec (FICTICIO) | C8: 30-72345678-4 | D8: Factura A | E8: Bebidas | F8: Compra de bebidas para operación | G8: 64107 | H8: 0.21 | I8: =ROUND(G8*H8,2) -> 13462.47 | J8: =ROUND(G8+I8,2) -> 77569.47 | K8: Tarjeta de débito
A9: 46126 | B9: Edenor - ejemplo didáctico | C9: 30-54567891-2 | D9: Factura B | E9: Electricidad | F9: Compra de electricidad para operación | G9: 150936 | H9: 0.21 | I9: =ROUND(G9*H9,2) -> 31696.56 | J9: =ROUND(G9+I9,2) -> 182632.56 | K9: Tarjeta de crédito
A10: 46129 | B10: Metrogas - ejemplo didáctico | C10: 30-65789123-4 | D10: Factura B | E10: Gas | F10: Compra de gas para operación | G10: 87286 | H10: 0.21 | I10: =ROUND(G10*H10,2) -> 18330.06 | J10: =ROUND(G10+I10,2) -> 105616.06 | K10: Transferencia
A11: 46132 | B11: Fibra Puerto (FICTICIO) | C11: 30-67891234-5 | D11: Factura A | E11: Internet | F11: Compra de internet para operación | G11: 20853 | H11: 0.21 | I11: =ROUND(G11*H11,2) -> 4379.13 | J11: =ROUND(G11+I11,2) -> 25232.13 | K11: Mercado Pago
A12: 46135 | B12: Limpieza del Puerto (FICTICIO) | C12: 30-68912345-6 | D12: Factura B | E12: Limpieza | F12: Compra de limpieza para operación | G12: 44327 | H12: 0.21 | I12: =ROUND(G12*H12,2) -> 9308.67 | J12: =ROUND(G12+I12,2) -> 53635.67 | K12: Efectivo
A13: 46138 | B13: Envases del Plata (FICTICIO) | C13: 30-69123456-7 | D13: Factura B | E13: Insumos | F13: Compra de insumos para operación | G13: 29792 | H13: 0.21 | I13: =ROUND(G13*H13,2) -> 6256.32 | J13: =ROUND(G13+I13,2) -> 36048.32 | K13: Tarjeta de débito
A14: 46114 | B14: Alquiler local Puerto Madero (FICTICIO) | C14: 30-61234567-8 | D14: Factura A | E14: Alquiler | F14: Compra de alquiler para operación | G14: 98732 | H14: 0.21 | I14: =ROUND(G14*H14,2) -> 20733.72 | J14: =ROUND(G14+I14,2) -> 119465.72 | K14: Tarjeta de crédito
A15: 46117 | B15: Mantenimiento Parrillero (FICTICIO) | C15: 30-63456789-1 | D15: Factura B | E15: Mantenimiento | F15: Compra de mantenimiento para operación | G15: 25714 | H15: 0.21 | I15: =ROUND(G15*H15,2) -> 5399.94 | J15: =ROUND(G15+I15,2) -> 31113.94 | K15: Transferencia
A16: 46120 | B16: Panificados del Puerto (FICTICIO) | C16: 30-64567891-3 | D16: Factura B | E16: Alimentos | F16: Compra de alimentos para operación | G16: 51479 | H16: 0.21 | I16: =ROUND(G16*H16,2) -> 10810.59 | J16: =ROUND(G16+I16,2) -> 62289.59 | K16: Mercado Pago
... A22: 46138 | B22: Papelería Administrativa (FICTICIO) | C22: 30-61234578-9 | D22: Factura B | E22: Administración | F22: Compra de administración para operación | G22: 11540 | H22: 0.21 | I22: =ROUND(G22*H22,2) -> 2423.4 | J22: =ROUND(G22+I22,2) -> 13963.4 | K22: Efectivo

Sheet Mayo Ventas
A1: COSTANERA GRILL · MAYO 2026 · REGISTRO DE VENTAS (SIMULACIÓN)
A2: Datos inventados para ejercicio de capacitación. Sin validez fiscal ni contable. IVA calculado con fórmula sobre base imponible.
A4: Fecha | B4: Tipo comprobante | C4: Número | D4: Cliente | E4: CUIT cliente (ficticio) | F4: Concepto | G4: Cantidad | H4: Neto gravado | I4: Alícuota IVA | J4: IVA débito | K4: Total | L4: Medio de cobro
A5: 46143 | B5: Factura A | C5: 0001-00005001 | D5: Estudio Madero (FICTICIO) | E5: 30-70057188-5 | F5: Parrilla y cortes | G5: 1 | H5: 131221 | I5: 0.21 | J5: =ROUND(H5*I5,2) -> 27556.41 | K5: =ROUND(H5+J5,2) -> 158777.41 | L5: Mercado Pago
A6: 46144 | B6: Factura B | C6: 0001-00005002 | D6: Consumidor final | F6: Menú ejecutivo | G6: 2 | H6: 54166 | I6: 0.21 | J6: =ROUND(H6*I6,2) -> 11374.86 | K6: =ROUND(H6+J6,2) -> 65540.86 | L6: Tarjeta de crédito
A7: 46145 | B7: Factura B | C7: 0001-00005003 | D7: Consumidor final | F7: Cortes premium | G7: 3 | H7: 67112 | I7: 0.21 | J7: =ROUND(H7*I7,2) -> 14093.52 | K7: =ROUND(H7+J7,2) -> 81205.52 | L7: Efectivo
A8: 46146 | B8: Factura B | C8: 0001-00005004 | D8: Consumidor final | F8: Bebidas y cubiertos | G8: 4 | H8: 80058 | I8: 0.21 | J8: =ROUND(H8*I8,2) -> 16812.18 | K8: =ROUND(H8+J8,2) -> 96870.18 | L8: Transferencia
A9: 46147 | B9: Factura B | C9: 0001-00005005 | D9: Consumidor final | F9: Parrilla y cortes | G9: 5 | H9: 93004 | I9: 0.21 | J9: =ROUND(H9*I9,2) -> 19530.84 | K9: =ROUND(H9+J9,2) -> 112534.84 | L9: Tarjeta de débito
A10: 46148 | B10: Factura B | C10: 0001-00005006 | D10: Empresa de Eventos Sur (FICTICIA) | F10: Menú ejecutivo | G10: 6 | H10: 105950 | I10: 0.21 | J10: =ROUND(H10*I10,2) -> 22249.5 | K10: =ROUND(H10+J10,2) -> 128199.5 | L10: Mercado Pago
A11: 46149 | B11: Factura B | C11: 0001-00005007 | D11: Consumidor final | F11: Cortes premium | G11: 1 | H11: 118896 | I11: 0.21 | J11: =ROUND(H11*I11,2) -> 24968.16 | K11: =ROUND(H11+J11,2) -> 143864.16 | L11: Tarjeta de crédito
A12: 46150 | B12: Factura B | C12: 0001-00005008 | D12: Agencia Costera (FICTICIA) | F12: Bebidas y cubiertos | G12: 2 | H12: 131842 | I12: 0.21 | J12: =ROUND(H12*I12,2) -> 27686.82 | K12: =ROUND(H12+J12,2) -> 159528.82 | L12: Efectivo
A13: 46151 | B13: Factura B | C13: 0001-00005009 | D13: Consumidor final | F13: Parrilla y cortes | G13: 3 | H13: 54787 | I13: 0.21 | J13: =ROUND(H13*I13,2) -> 11505.27 | K13: =ROUND(H13+J13,2) -> 66292.27 | L13: Transferencia
A14: 46152 | B14: Factura B | C14: 0001-00005010 | D14: Hotel Dársena (FICTICIO) | F14: Menú ejecutivo | G14: 4 | H14: 67733 | I14: 0.21 | J14: =ROUND(H14*I14,2) -> 14223.93 | K14: =ROUND(H14+J14,2) -> 81956.93 | L14: Tarjeta de débito
A15: 46153 | B15: Factura A | C15: 0001-00005011 | D15: Consumidor final | E15: 30-70059398-7 | F15: Cortes premium | G15: 5 | H15: 80679 | I15: 0.21 | J15: =ROUND(H15*I15,2) -> 16942.59 | K15: =ROUND(H15+J15,2) -> 97621.59 | L15: Mercado Pago
A16: 46154 | B16: Factura B | C16: 0001-00005012 | D16: Consultora Río (FICTICIA) | F16: Bebidas y cubiertos | G16: 6 | H16: 93625 | I16: 0.21 | J16: =ROUND(H16*I16,2) -> 19661.25 | K16: =ROUND(H16+J16,2) -> 113286.25 | L16: Tarjeta de crédito
A17: 46155 | B17: Factura B | C17: 0001-00005013 | D17: Estudio Madero (FICTICIO) | F17: Parrilla y cortes | G17: 1 | H17: 106571 | I17: 0.21 | J17: =ROUND(H17*I17,2) -> 22379.91 | K17: =ROUND(H17+J17,2) -> 128950.91 | L17: Efectivo
A18: 46156 | B18: Factura B | C18: 0001-00005014 | D18: Consumidor final | F18: Menú ejecutivo | G18: 2 | H18: 119517 | I18: 0.21 | J18: =ROUND(H18*I18,2) -> 25098.57 | K18: =ROUND(H18+J18,2) -> 144615.57 | L18: Transferencia
A19: 46157 | B19: Factura B | C19: 0001-00005015 | D19: Consumidor final | F19: Cortes premium | G19: 3 | H19: 42462 | I19: 0.21 | J19: =ROUND(H19*I19,2) -> 8917.02 | K19: =ROUND(H19+J19,2) -> 51379.02 | L19: Tarjeta de débito
A20: 46158 | B20: Factura B | C20: 0001-00005016 | D20: Consumidor final | F20: Bebidas y cubiertos | G20: 4 | H20: 55408 | I20: 0.21 | J20: =ROUND(H20*I20,2) -> 11635.68 | K20: =ROUND(H20+J20,2) -> 67043.68 | L20: Mercado Pago
A21: 46159 | B21: Factura B | C21: 0001-00005017 | D21: Consumidor final | F21: Parrilla y cortes | G21: 5 | H21: 68354 | I21: 0.21 | J21: =ROUND(H21*I21,2) -> 14354.34 | K21: =ROUND(H21+J21,2) -> 82708.34 | L21: Tarjeta de crédito
A22: 46160 | B22: Factura B | C22: 0001-00005018 | D22: Empresa de Eventos Sur (FICTICIA) | F22: Menú ejecutivo | G22: 6 | H22: 81300 | I22: 0.21 | J22: =ROUND(H22*I22,2) -> 17073 | K22: =ROUND(H22+J22,2) -> 98373 | L22: Efectivo
A23: 46161 | B23: Factura B | C23: 0001-00005019 | D23: Consumidor final | F23: Cortes premium | G23: 1 | H23: 94246 | I23: 0.21 | J23: =ROUND(H23*I23,2) -> 19791.66 | K23: =ROUND(H23+J23,2) -> 114037.66 | L23: Transferencia
A24: 46162 | B24: Factura B | C24: 0001-00005020 | D24: Agencia Costera (FICTICIA) | F24: Bebidas y cubiertos | G24: 2 | H24: 107192 | I24: 0.21 | J24: =ROUND(H24*I24,2) -> 22510.32 | K24: =ROUND(H24+J24,2) -> 129702.32 | L24: Tarjeta de débito
A25: 46163 | B25: Factura A | C25: 0001-00005021 | D25: Consumidor final | E25: 30-70061608-1 | F25: Parrilla y cortes | G25: 3 | H25: 120138 | I25: 0.21 | J25: =ROUND(H25*I25,2) -> 25228.98 | K25: =ROUND(H25+J25,2) -> 145366.98 | L25: Mercado Pago
A26: 46164 | B26: Factura B | C26: 0001-00005022 | D26: Hotel Dársena (FICTICIO) | F26: Menú ejecutivo | G26: 4 | H26: 43083 | I26: 0.21 | J26: =ROUND(H26*I26,2) -> 9047.43 | K26: =ROUND(H26+J26,2) -> 52130.43 | L26: Tarjeta de crédito
A27: 46165 | B27: Factura B | C27: 0001-00005023 | D27: Consumidor final | F27: Cortes premium | G27: 5 | H27: 56029 | I27: 0.21 | J27: =ROUND(H27*I27,2) -> 11766.09 | K27: =ROUND(H27+J27,2) -> 67795.09 | L27: Efectivo
A28: 46166 | B28: Factura B | C28: 0001-00005024 | D28: Consultora Río (FICTICIA) | F28: Bebidas y cubiertos | G28: 6 | H28: 68975 | I28: 0.21 | J28: =ROUND(H28*I28,2) -> 14484.75 | K28: =ROUND(H28+J28,2) -> 83459.75 | L28: Transferencia
A29: 46167 | B29: Factura B | C29: 0001-00005025 | D29: Estudio Madero (FICTICIO) | F29: Parrilla y cortes | G29: 1 | H29: 81921 | I29: 0.21 | J29: =ROUND(H29*I29,2) -> 17203.41 | K29: =ROUND(H29+J29,2) -> 99124.41 | L29: Tarjeta de débito
A30: 46168 | B30: Factura B | C30: 0001-00005026 | D30: Consumidor final | F30: Menú ejecutivo | G30: 2 | H30: 94867 | I30: 0.21 | J30: =ROUND(H30*I30,2) -> 19922.07 | K30: =ROUND(H30+J30,2) -> 114789.07 | L30: Mercado Pago
A31: 46169 | B31: Factura B | C31: 0001-00005027 | D31: Consumidor final | F31: Cortes premium | G31: 3 | H31: 107813 | I31: 0.21 | J31: =ROUND(H31*I31,2) -> 22640.73 | K31: =ROUND(H31+J31,2) -> 130453.73 | L31: Tarjeta de crédito
A32: 46170 | B32: Factura B | C32: 0001-00005028 | D32: Consumidor final | F32: Bebidas y cubiertos | G32: 4 | H32: 120759 | I32: 0.21 | J32: =ROUND(H32*I32,2) -> 25359.39 | K32: =ROUND(H32+J32,2) -> 146118.39 | L32: Efectivo
A33: 46143 | B33: Factura B | C33: 0001-00005029 | D33: Consumidor final | F33: Parrilla y cortes | G33: 5 | H33: 43704 | I33: 0.21 | J33: =ROUND(H33*I33,2) -> 9177.84 | K33: =ROUND(H33+J33,2) -> 52881.84 | L33: Transferencia
A34: 46144 | B34: Factura B | C34: 0001-00005030 | D34: Empresa de Eventos Sur (FICTICIA) | F34: Menú ejecutivo | G34: 6 | H34: 56650 | I34: 0.21 | J34: =ROUND(H34*I34,2) -> 11896.5 | K34: =ROUND(H34+J34,2) -> 68546.5 | L34: Tarjeta de débito
A35: 46145 | B35: Factura A | C35: 0001-00005031 | D35: Consumidor final | E35: 30-70063818-3 | F35: Cortes premium | G35: 1 | H35: 69596 | I35: 0.21 | J35: =ROUND(H35*I35,2) -> 14615.16 | K35: =ROUND(H35+J35,2) -> 84211.16 | L35: Mercado Pago
A36: 46146 | B36: Factura B | C36: 0001-00005032 | D36: Agencia Costera (FICTICIA) | F36: Bebidas y cubiertos | G36: 2 | H36: 82542 | I36: 0.21 | J36: =ROUND(H36*I36,2) -> 17333.82 | K36: =ROUND(H36+J36,2) -> 99875.82 | L36: Tarjeta de crédito
A37: 46147 | B37: Factura B | C37: 0001-00005033 | D37: Consumidor final | F37: Parrilla y cortes | G37: 3 | H37: 95488 | I37: 0.21 | J37: =ROUND(H37*I37,2) -> 20052.48 | K37: =ROUND(H37+J37,2) -> 115540.48 | L37: Efectivo
A38: 46148 | B38: Factura B | C38: 0001-00005034 | D38: Hotel Dársena (FICTICIO) | F38: Menú ejecutivo | G38: 4 | H38: 108434 | I38: 0.21 | J38: =ROUND(H38*I38,2) -> 22771.14 | K38: =ROUND(H38+J38,2) -> 131205.14 | L38: Transferencia
A39: 46149 | B39: Factura B | C39: 0001-00005035 | D39: Consumidor final | F39: Cortes premium | G39: 5 | H39: 121380 | I39: 0.21 | J39: =ROUND(H39*I39,2) -> 25489.8 | K39: =ROUND(H39+J39,2) -> 146869.8 | L39: Tarjeta de débito
A40: 46150 | B40: Factura B | C40: 0001-00005036 | D40: Consultora Río (FICTICIA) | F40: Bebidas y cubiertos | G40: 6 | H40: 44325 | I40: 0.21 | J40: =ROUND(H40*I40,2) -> 9308.25 | K40: =ROUND(H40+J40,2) -> 53633.25 | L40: Mercado Pago
